<mujoco model="velocity_zbot">
  <option timestep="0.005" iterations="10" ls_iterations="20" solver="Newton" integrator="implicitfast"/>
  <compiler angle="radian" meshdir="assets"/>

  <default>
    <default class="zbot">
      <default class="sts3215">
        <joint damping="0.60" frictionloss="0.052" armature="0.028"/>
        <position kp="17.8" kv="0.0" forcerange="-3.35 3.35"/>
      </default>
      <joint armature="0.01" frictionloss="0.2" damping="1" limited="true"/>
      <default class="visual">
        <geom material="visualgeom" contype="0" conaffinity="0" group="2" />
      </default>
      <default class="collision">
        <geom material="collision_material" group="3" friction="0.6" rgba=".2 .6 .2 .3" type="capsule"/>
      </default>
    </default>
  </default>

  <worldbody>
    <geom name="floor" size="0 0 0.01" type="plane" material="groundplane" priority="1" friction="0.6" condim="3"/>

    <body name="floating_base" pos="0.0 0.0 0.4" childclass="zbot">
      <camera name="default" pos="1.734 -1.135 .35" xyaxes="0.552 0.834 -0.000 -0.170 0.112 0.979" mode="trackcom"/>
      <freejoint name="floating_base" />
      <geom name="torso_collision" type="sphere" size="0.042" pos="-0.005 0 -0.035" class="collision"/>
      <light pos="0 0 2" mode="trackcom"/>
      <geom name="floating_base_link_visual" quat="0.7073882691671998 0.0 0.0 0.706825181105366" material="floating_base_link_material" type="sphere" size="0.01" class="visual" />

      <body name="Z_BOT2_MASTER_BODY_SKELETON" quat="0.7073882691671998 0.0 0.0 0.706825181105366">
        <inertial pos="-0.000189 0.010193 -0.031201" mass="1.546392" diaginertia="0.004795 0.005455 0.002588" />
        <geom name="Z_BOT2_MASTER_BODY_SKELETON_visual" material="Z_BOT2_MASTER_BODY_SKELETON_material" type="mesh" mesh="Z_BOT2_MASTER_BODY_SKELETON.stl" class="visual" />

        <body name="IMU" pos="0.044470 0.006575 -0.025518" quat="0.5000001633974483 0.4999999999999733 -0.49999983660255165 -0.4999999999999733">
          <inertial pos="-0.010000 -0.007500 -0.001235" mass="0.001887" diaginertia="1e-06 1e-06 1e-06" />
          <geom name="IMU" material="IMU_material" type="mesh" mesh="IMU.stl" class="visual" />
          <site name="IMU" quat="0.707106841 -0.707106610 0.000281428 0.000281429" pos="0.0 0.0 0.0" />
        </body>

        <!-- Left arm -->
        <body name="Z_BOT2_MASTER_SHOULDER2" pos="0.055995 -0.010610 -0.009528" quat="-1.2247452309842457e-07 -1.22474483074382e-07 -0.7071066656470838 -0.7071068967259713">
          <joint name="left_shoulder_yaw"   type="hinge" class="sts3215" ref="0.0" range="-0.972 0.51" axis="0 0 1" />
          <inertial pos="-0.012788 0.001374 0.018800" mass="0.024098" diaginertia="7e-06 8e-06 3e-06" />
          <geom name="Z_BOT2_MASTER_SHOULDER2_visual" material="Z_BOT2_MASTER_SHOULDER2_material" type="mesh" mesh="Z_BOT2_MASTER_SHOULDER2.stl" class="visual" />
          <body name="3215_1Flange" pos="-0.020845 -0.004900 0.018800" quat="0.5000001633974483 -0.4999999999999733 0.49999983660255165 -0.4999999999999733">
            <joint name="left_shoulder_pitch" type="hinge" class="sts3215" ref="0.0" range="-1.55 1" axis="0 0 -1" />
            <inertial pos="0.033642 0.000438 -0.019963" mass="0.181960" diaginertia="5.4e-05 0.000228 0.000232" />
            <geom name="3215_1Flange_visual" material="3215_1Flange_material" type="mesh" mesh="3215_1Flange.stl" class="visual" />
            <body name="R_ARM_MIRROR_1" pos="0.092984 0.019800 -0.018600" quat="-1.2247452309842457e-07 -1.22474483074382e-07 0.7071066656470838 0.7071068967259713">
              <geom name="left_elbow_collision" size="0.015" pos="0 0 -0.018" type="sphere" class="collision"/>
              <joint name="left_elbow" type="hinge" class="sts3215" ref="0.0" range="0 1.5" axis="0 0 -1" />
              <inertial pos="-0.051119 0.001150 -0.017743" mass="0.186073" diaginertia="6.1e-05 0.000218 0.000201" />
              <geom name="R_ARM_MIRROR_1_visual" material="R_ARM_MIRROR_1_material" type="mesh" mesh="R_ARM_MIRROR_1.stl" class="visual" />
              <body name="FINGER_1" pos="-0.066206 -0.011778 0.001260" quat="-9.934637848443371e-08 0.5735765089253517 0.8191519934718928 -1.418813056556475e-07">
                <joint name="left_gripper" type="hinge" class="sts3215" ref="0.0" range="-0.349066 0.698132" axis="0 0 1" />
                <inertial pos="-0.010671 -0.028985 0.018800" mass="0.044318" diaginertia="2.3e-05 1e-05 1.6e-05" />
                <geom name="FINGER_1_visual" material="L_ARM_MIRROR_1_material" type="mesh" mesh="FINGER_1.stl" class="visual" />
              </body>
            </body>
          </body>
        </body>

        <!-- Right arm -->
        <body name="Z_BOT2_MASTER_SHOULDER2_2" pos="-0.055995 -0.010610 -0.009528" quat="0.7071068967259818 -0.7071066656470943 0.0 0.0">
          <joint name="right_shoulder_yaw"  type="hinge" class="sts3215" ref="0.0" range="-0.51 0.972" axis="0 0 1" />
          <inertial pos="-0.012788 -0.001374 0.018800" mass="0.024098" diaginertia="7e-06 8e-06 3e-06" />
          <geom name="Z_BOT2_MASTER_SHOULDER2_2_visual" material="Z_BOT2_MASTER_SHOULDER2_material" type="mesh" mesh="Z_BOT2_MASTER_SHOULDER2_2.stl" class="visual" />
          <body name="3215_1Flange_2" pos="-0.020845 0.004900 0.018800" quat="0.5000001633974483 0.4999999999999733 0.49999983660255165 0.4999999999999733">
            <geom name="left_shoulder_collision" size="0.015" pos="0 0 -0.018" type="sphere" class="collision"/>
            <joint name="right_shoulder_pitch" type="hinge" class="sts3215" ref="0.0" range="-1 1.55" axis="0 0 -1" />
            <inertial pos="0.033642 -0.000433 -0.019968" mass="0.181960" diaginertia="5.4e-05 0.000228 0.000232" />
            <geom name="3215_1Flange_2_visual" material="3215_1Flange_material" type="mesh" mesh="3215_1Flange_2.stl" class="visual" />
            <body name="L_ARM_MIRROR_1" pos="0.092984 -0.019800 -0.018600" quat="0.5000001633974483 -0.4999999999999733 -0.4999999999999733 -0.49999983660255165">
              <geom name="right_elbow_collision" size="0.015" pos="0 0 0.018" type="sphere" class="collision"/>
              <joint name="right_elbow" type="hinge" class="sts3215" ref="0.0" range="-1.5 0" axis="0 0 1" />
              <inertial pos="0.001144 0.051123 0.017764" mass="0.186073" diaginertia="0.000218 6.1e-05 0.000201" />
              <geom name="L_ARM_MIRROR_1_visual" material="L_ARM_MIRROR_1_material" type="mesh" mesh="L_ARM_MIRROR_1.stl" class="visual" />
              <body name="FINGER_1_2" pos="-0.011778 0.066206 -0.001260" quat="0.9848077400232231 0.0 0.0 0.1736482513311082">
                <joint name="right_gripper" type="hinge" class="sts3215" ref="0.0" range="-0.698132 0.349066" axis="0 0 1" />
                <inertial pos="-0.010671 0.028985 0.018799" mass="0.044318" diaginertia="2.3e-05 1e-05 1.6e-05" />
                <geom name="FINGER_1_2_visual" material="L_ARM_MIRROR_1_material" type="mesh" mesh="FINGER_1_2.stl" class="visual" />
              </body>
            </body>
          </body>
        </body>

        <!-- Left leg -->
        <body name="U_HIP_L" pos="0.042808 0.007735 -0.083418" quat="3.000000781252362e-14 -1.7320510330969674e-07 0.99999999999997 -1.7320510330969674e-07">
          <joint name="left_hip_yaw"   type="hinge" class="sts3215" ref="0.0" range="-0.22 0.12" axis="0 0 1" />
          <inertial pos="-0.001161 -0.004396 0.035396" mass="0.047132" diaginertia="2.9e-05 3e-05 1.9e-05" />
          <geom name="U_HIP_L_visual" material="U_HIP_L_material" type="mesh" mesh="U_HIP_L.stl" class="visual" />

          <body name="3215_BothFlange_5" pos="0 0.017700 0.056400" quat="0.7071068967259818 -0.7071066656470943 0.0 0.0">
            <joint name="left_hip_roll"  type="hinge" class="sts3215" ref="0.0" range="0 0.56" axis="0 0 -1" />
            <inertial pos="0.012332 -0.008997 -0.018508" mass="0.068295" diaginertia="1.9e-05 2.4e-05 2.5e-05" />
            <geom name="3215_BothFlange_5_visual" material="floating_base_link_material" type="mesh" mesh="3215_BothFlange_5.stl" class="visual" />

            <body name="3215_BothFlange_9" pos="-0.006400 -0.032000 -0.017900" quat="0.5000001633974483 0.4999999999999733 -0.49999983660255165 -0.4999999999999733">
              <geom name="left_hip_collision" size="0.015" pos="0 0 -0.018" type="sphere" class="collision"/>
              <joint name="left_hip_pitch" type="hinge" class="sts3215" ref="0.0" range="-1.75 1.35" axis="0 0 1" />
              <inertial pos="0.043662 -0.002857 -0.018525" mass="0.143337" diaginertia="4.9e-05 0.000148 0.000128" />
              <geom name="3215_BothFlange_9_visual" material="floating_base_link_material" type="mesh" mesh="3215_BothFlange_9.stl" class="visual" />

              <body name="3215_BothFlange_13" pos="0.100000 0.010000 -0.001260">
                <geom name="left_knee_collision" size="0.015" pos="0 0 -0.018" type="sphere" class="collision"/>
                <joint name="left_knee" type="hinge" class="sts3215" ref="0.0" range="0 1.81" axis="0 0 1" />
                <inertial pos="0.050000 0 -0.017988" mass="0.128213" diaginertia="3.5e-05 0.000154 0.000145" />
                <geom name="3215_BothFlange_13_visual" material="floating_base_link_material" type="mesh" mesh="3215_BothFlange_13.stl" class="visual" />

                <body name="FOOT" pos="0.100000 0 0.000800" quat="-1.2247452309842457e-07 -0.7071068967259713 -0.7071066656470838 -1.22474483074382e-07">
                  <joint name="left_ankle" type="hinge" class="sts3215" ref="0.0" range="-0.7 0.7" axis="0 0 1" />
                  <inertial pos="-0.015078 0.027835 0.018700" mass="0.278140" diaginertia="4.5e-05 0.000205 0.000182" />
                  <geom name="FOOT_visual" material="L_ARM_MIRROR_1_material" type="mesh" mesh="FOOT.stl" class="visual" />
                  <site name="left_foot" size="0.002" pos="0.0 0.038 0.02" type="sphere" />
                  <geom name="left_foot_collision1" type="capsule" fromto="-0.053 0.028 0.010   0.020 0.028 0.010" size="0.008" class="collision"/>
                  <geom name="left_foot_collision2" type="capsule" fromto="-0.053 0.028 0.028   0.020 0.028 0.028" size="0.008" class="collision"/>
                </body>
              </body>
            </body>
          </body>
        </body>

        <!-- Right leg -->
        <body name="U_HIP_R" pos="-0.042868 0.007735 -0.083418" quat="3.000000781252362e-14 -1.7320510330969674e-07 0.99999999999997 -1.7320510330969674e-07">
          <joint name="right_hip_yaw"  type="hinge" class="sts3215" ref="0.0" range="-0.12 0.22" axis="0 0 1" />
          <inertial pos="0.001161 -0.004396 0.035396" mass="0.047132" diaginertia="2.9e-05 3e-05 1.9e-05" />
          <geom name="U_HIP_R_visual" material="U_HIP_L_material" type="mesh" mesh="U_HIP_R.stl" class="visual" />

          <body name="3215_BothFlange_6" pos="0 -0.017700 0.056400" quat="-1.2247452309842457e-07 1.22474483074382e-07 0.7071066656470838 -0.7071068967259713">
            <joint name="right_hip_roll" type="hinge" class="sts3215" ref="0.0" range="-0.56 0" axis="0 0 1" />
            <inertial pos="0.012332 -0.008983 -0.017811" mass="0.068295" diaginertia="1.9e-05 2.4e-05 2.5e-05" />
            <geom name="3215_BothFlange_6_visual" material="floating_base_link_material" type="mesh" mesh="3215_BothFlange_6.stl" class="visual" />

            <body name="3215_BothFlange_10" pos="-0.006400 -0.032000 -0.018900" quat="0.5000001633974483 0.4999999999999733 -0.49999983660255165 -0.4999999999999733">
              <geom name="right_hip_collision" size="0.015" pos="0 0 -0.018" type="sphere" class="collision"/>
              <joint name="right_hip_pitch" type="hinge" class="sts3215" ref="0.0" range="-1.35 1.75" axis="0 0 1" />
              <inertial pos="0.043662 0.002863 -0.018537" mass="0.143337" diaginertia="4.9e-05 0.000148 0.000128" />
              <geom name="3215_BothFlange_10_visual" material="floating_base_link_material" type="mesh" mesh="3215_BothFlange_10.stl" class="visual" />

              <body name="3215_BothFlange_14" pos="0.100000 -0.010000 -0.001260">
                <geom name="right_knee_collision" size="0.015" pos="0 0 -0.018" type="sphere" class="collision"/>
                <joint name="right_knee" type="hinge" class="sts3215" ref="0.0" range="0 1.81" axis="0 0 -1" />
                <inertial pos="0.050000 0 -0.017888" mass="0.128213" diaginertia="3.6e-05 0.000155 0.000145" />
                <geom name="3215_BothFlange_14_visual" material="floating_base_link_material" type="mesh" mesh="3215_BothFlange_14.stl" class="visual" />

                <body name="FOOT_2" pos="0.100000 0 0.001000" quat="-1.2247452309842457e-07 -0.7071068967259713 0.7071066656470838 1.22474483074382e-07">
                  <joint name="right_ankle" type="hinge" class="sts3215" ref="0.0" range="-0.7 0.7" axis="0 0 1" />
                  <inertial pos="-0.015078 -0.027835 0.018700" mass="0.278140" diaginertia="4.5e-05 0.000205 0.000182" />
                  <geom name="FOOT_2_visual" material="L_ARM_MIRROR_1_material" type="mesh" mesh="FOOT_2.stl" class="visual" />
                  <site name="right_foot" size="0.002" pos="0.0 -0.038 0.02" type="sphere" />
                  <geom name="right_foot_collision1" type="capsule" fromto="-0.053 -0.028 0.010   0.020 -0.028 0.010" size="0.008" class="collision"/>
                  <geom name="right_foot_collision2" type="capsule" fromto="-0.053 -0.028 0.028   0.020 -0.028 0.028" size="0.008" class="collision"/>
                </body>
              </body>
            </body>
          </body>
        </body>
      </body>

      <site name="floating_base_link_site" />
      <camera name="front_camera" mode="track" fovy="90.0" quat="4.329780281177467e-17 4.329780281177466e-17 0.7071067811865475 0.7071067811865476" pos="0.0 2.0 0.5" />
      <camera name="side_camera" mode="track" fovy="90.0" quat="-0.5 -0.4999999999999999 0.5 0.5000000000000001" pos="-2.0 0.0 0.5" />
    </body>
  </worldbody>

  <actuator>
    <position name="left_shoulder_yaw_ctrl"    joint="left_shoulder_yaw"    class="sts3215"/>
    <position name="left_shoulder_pitch_ctrl"  joint="left_shoulder_pitch"  class="sts3215"/>
    <position name="left_elbow_ctrl"           joint="left_elbow"           class="sts3215"/>
    <position name="left_gripper_ctrl"         joint="left_gripper"         class="sts3215"/>

    <position name="right_shoulder_yaw_ctrl"   joint="right_shoulder_yaw"   class="sts3215"/>
    <position name="right_shoulder_pitch_ctrl" joint="right_shoulder_pitch" class="sts3215"/>
    <position name="right_elbow_ctrl"          joint="right_elbow"          class="sts3215"/>
    <position name="right_gripper_ctrl"        joint="right_gripper"        class="sts3215"/>

    <position name="left_hip_yaw_ctrl"         joint="left_hip_yaw"         class="sts3215"/>
    <position name="left_hip_roll_ctrl"        joint="left_hip_roll"        class="sts3215"/>
    <position name="left_hip_pitch_ctrl"       joint="left_hip_pitch"       class="sts3215"/>
    <position name="left_knee_ctrl"            joint="left_knee"            class="sts3215"/>
    <position name="left_ankle_ctrl"           joint="left_ankle"           class="sts3215"/>

    <position name="right_hip_yaw_ctrl"        joint="right_hip_yaw"        class="sts3215"/>
    <position name="right_hip_roll_ctrl"       joint="right_hip_roll"       class="sts3215"/>
    <position name="right_hip_pitch_ctrl"      joint="right_hip_pitch"      class="sts3215"/>
    <position name="right_knee_ctrl"           joint="right_knee"           class="sts3215"/>
    <position name="right_ankle_ctrl"          joint="right_ankle"          class="sts3215"/>
  </actuator>

  <contact>
    <exclude body1="3215_1Flange" body2="R_ARM_MIRROR_1" />
    <exclude body1="3215_1Flange_2" body2="L_ARM_MIRROR_1" />
    <exclude body1="3215_BothFlange_9" body2="3215_BothFlange_13" />
    <exclude body1="3215_BothFlange_10" body2="3215_BothFlange_14" />
    <exclude body1="R_ARM_MIRROR_1" body2="FINGER_1" />
    <exclude body1="L_ARM_MIRROR_1" body2="FINGER_1_2" />
    <exclude body1="3215_BothFlange_13" body2="FOOT" />
    <exclude body1="3215_BothFlange_14" body2="FOOT_2" />
  </contact>

  <sensor>
    <gyro name="gyro" site="IMU" noise="0.01" />
    <accelerometer name="accelerometer" site="IMU" noise="0.01" />
    <velocimeter name="local_linvel" site="IMU" />
    <framezaxis name="gravity" objtype="site" objname="IMU"/>

    <framelinvel name="global_linvel" objtype="site" objname="floating_base_link_site" />
    <frameangvel name="global_angvel" objtype="site" objname="floating_base_link_site" />

    <contact name="left_foot_floor_contact" body1="FOOT" geom2="floor" reduce="mindist" num="1" data="found"/>
    <contact name="right_foot_floor_contact" body1="FOOT_2" geom2="floor" reduce="mindist" num="1" data="found"/>
  </sensor>

  <keyframe>
    <key name="home"
        qpos="0 0 0.39 1 0 0 0 
        0 -0.53 0.44 0 
        0 0.53 -0.44 0 

        0 0 -0.4635 1.079 0.6 
        0 0 0.4635 1.079 -0.6"

        ctrl="
        0 -0.53 0.44 0 
        0 0.53 -0.44 0 
        0 0 -0.4635 1.079 0.6 
        0 0 0.4635 1.079 -0.6"
    />
  </keyframe>

  <asset>
    <material name="collision_material" rgba="1.0 0.28 0.1 0.9" />
    <material name="floating_base_link_material" rgba="1 0 0 1" />
    <material name="Z_BOT2_MASTER_BODY_SKELETON_material" rgba="0.494118 0.623529 0.749020 1" />
    <material name="IMU_material" rgba="0 1 0 1" />
    <material name="Z_BOT2_MASTER_SHOULDER2_material" rgba="0.364706 0.360784 0.749020 1" />
    <material name="U_HIP_L_material" rgba="0.768627 0.886275 0.952941 1" />
    <material name="3215_1Flange_material" rgba="0.749020 0.498039 0.725490 1" />
    <material name="R_ARM_MIRROR_1_material" rgba="0.647059 0.647059 0.647059 1" />
    <material name="L_ARM_MIRROR_1_material" rgba="0.627451 0.627451 0.627451 1" />
    <material name="default_material" rgba="0.7 0.7 0.7 1" />
    <mesh name="Z_BOT2_MASTER_BODY_SKELETON.collision.stl" file="Z_BOT2_MASTER_BODY_SKELETON.collision.stl" />
    <mesh name="Z_BOT2_MASTER_BODY_SKELETON.stl" file="Z_BOT2_MASTER_BODY_SKELETON.stl" />
    <mesh name="IMU.stl" file="IMU.stl" />
    <mesh name="Z_BOT2_MASTER_SHOULDER2.stl" file="Z_BOT2_MASTER_SHOULDER2.stl" />
    <mesh name="3215_1Flange.collision.stl" file="3215_1Flange.collision.stl" />
    <mesh name="3215_1Flange.stl" file="3215_1Flange.stl" />
    <mesh name="R_ARM_MIRROR_1.collision.stl" file="R_ARM_MIRROR_1.collision.stl" />
    <mesh name="R_ARM_MIRROR_1.stl" file="R_ARM_MIRROR_1.stl" />
    <mesh name="FINGER_1.collision.stl" file="FINGER_1.collision.stl" />
    <mesh name="FINGER_1.stl" file="FINGER_1.stl" />
    <mesh name="Z_BOT2_MASTER_SHOULDER2_2.stl" file="Z_BOT2_MASTER_SHOULDER2_2.stl" />
    <mesh name="3215_1Flange_2.collision.stl" file="3215_1Flange_2.collision.stl" />
    <mesh name="3215_1Flange_2.stl" file="3215_1Flange_2.stl" />
    <mesh name="L_ARM_MIRROR_1.collision.stl" file="L_ARM_MIRROR_1.collision.stl" />
    <mesh name="L_ARM_MIRROR_1.stl" file="L_ARM_MIRROR_1.stl" />
    <mesh name="FINGER_1_2.collision.stl" file="FINGER_1_2.collision.stl" />
    <mesh name="FINGER_1_2.stl" file="FINGER_1_2.stl" />
    <mesh name="U_HIP_L.stl" file="U_HIP_L.stl" />
    <mesh name="3215_BothFlange_5.stl" file="3215_BothFlange_5.stl" />
    <mesh name="3215_BothFlange_9.collision.stl" file="3215_BothFlange_9.collision.stl" />
    <mesh name="3215_BothFlange_9.stl" file="3215_BothFlange_9.stl" />
    <mesh name="3215_BothFlange_13.collision.stl" file="3215_BothFlange_13.collision.stl" />
    <mesh name="3215_BothFlange_13.stl" file="3215_BothFlange_13.stl" />
    <mesh name="FOOT.collision.stl" file="FOOT.collision.stl" />
    <mesh name="FOOT.stl" file="FOOT.stl" />
    <mesh name="U_HIP_R.stl" file="U_HIP_R.stl" />
    <mesh name="3215_BothFlange_6.stl" file="3215_BothFlange_6.stl" />
    <mesh name="3215_BothFlange_10.collision.stl" file="3215_BothFlange_10.collision.stl" />
    <mesh name="3215_BothFlange_10.stl" file="3215_BothFlange_10.stl" />
    <mesh name="3215_BothFlange_14.collision.stl" file="3215_BothFlange_14.collision.stl" />
    <mesh name="3215_BothFlange_14.stl" file="3215_BothFlange_14.stl" />
    <mesh name="FOOT_2.collision.stl" file="FOOT_2.collision.stl" />
    <mesh name="FOOT_2.stl" file="FOOT_2.stl" />

    <texture type="skybox" builtin="gradient" rgb1="1 1 1" rgb2="1 1 1" width="800" height="800"/>
    <texture type="2d" name="groundplane" builtin="checker" mark="edge" rgb1="1 1 1" rgb2="1 1 1" markrgb="0 0 0" width="300" height="300"/>
    <material name="groundplane" texture="groundplane" texuniform="true" texrepeat="5 5" reflectance="0"/>
  </asset>
</mujoco>
