<mujoco model="velocity_quadruped">
  <default>
    <default class="quadruped">
      <geom type="capsule" material="body" density="5" friction="1 0.5 0.5"/>
    </default>
    <default class="visual">
      <geom group="2" density="0" contype="0" conaffinity="0"/>
    </default>
    <joint armature="1" damping="1" limited="true"/>
  </default>

  <worldbody>
    <!-- Quadruped -->
    <body name="quadruped" childclass="quadruped" pos="0 0 0.75">
      <joint name="quadruped_root" type="free" armature="0" damping="0" limited="false" margin="0.01" pos="0 0 0"/>
      <light pos="0 0 2" mode="trackcom"/>
      <camera name="default" mode="trackcom" pos="3.659 -8.426 1.448" xyaxes="0.932 0.363 0.000 -0.075 0.193 0.978"/>
      <site name="imu" quat="1.0 0.0 0.0 0.0" pos="0.0 0.0 0.0" />
      <site name="quadruped" size="0.01" pos="0 0 0"/>
      <geom name="quadruped_torso" pos="0 0 0" size="0.25" type="sphere"/>

      <body name="quadruped_front_left_leg" pos="0 0 0">
        <geom name="quadruped_front_left_aux" fromto="0.0 0.0 0.0 0.2 0.2 0.0" size="0.08" type="capsule"/>
        <body name="quadruped_front_left_aux" pos="0.2 0.2 0">
          <joint name="quadruped_front_left_hip" axis="0 0 1" pos="0.0 0.0 0.0" range="-30 30" type="hinge"/>
          <geom name="quadruped_front_left_leg" fromto="0.0 0.0 0.0 0.2 0.2 0.0" size="0.08" type="capsule"/>
          <body name="quadruped_front_left_knee" pos="0.2 0.2 0">
            <joint name="quadruped_front_left_ankle" axis="-1 1 0" pos="0.0 0.0 0.0" range="30 70" type="hinge"/>
            <geom name="quadruped_front_left_ankle" fromto="0.0 0.0 0.0 0.4 0.4 0.0" size="0.08" type="capsule"/>
            <geom name="quadruped_front_left_foot" pos="0.4 0.4 0" size="0.08" type="sphere" mass="0"/>
            <site name="quadruped_front_left_foot" pos="0.435 0.435 0" size="0.03" type="sphere"/>
          </body>
        </body>
      </body>

      <body name="quadruped_front_right_leg" pos="0 0 0">
        <geom name="quadruped_front_right_aux" fromto="0.0 0.0 0.0 -0.2 0.2 0.0" size="0.08" type="capsule"/>
        <body name="quadruped_front_right_aux" pos="-0.2 0.2 0">
          <joint name="quadruped_front_right_hip" axis="0 0 1" pos="0.0 0.0 0.0" range="-30 30" type="hinge"/>
          <geom name="quadruped_front_right_leg" fromto="0.0 0.0 0.0 -0.2 0.2 0.0" size="0.08" type="capsule"/>
          <body name="quadruped_front_right_knee" pos="-0.2 0.2 0">
            <joint name="quadruped_front_right_ankle" axis="1 1 0" pos="0.0 0.0 0.0" range="-70 -30" type="hinge"/>
            <geom name="quadruped_front_right_ankle" fromto="0.0 0.0 0.0 -0.4 0.4 0.0" size="0.08" type="capsule"/>
            <geom name="quadruped_front_right_foot" pos="-0.4 0.4 0" size="0.08" type="sphere" mass="0"/>
            <site name="quadruped_front_right_foot" pos="-0.435 0.435 0" size="0.03" type="sphere"/>
          </body>
        </body>
      </body>

      <body name="quadruped_back_left_leg" pos="0 0 0">
        <geom name="quadruped_back_left_aux" fromto="0.0 0.0 0.0 -0.2 -0.2 0.0" size="0.08" type="capsule"/>
        <body name="quadruped_back_left_aux" pos="-0.2 -0.2 0">
          <joint name="quadruped_back_left_hip" axis="0 0 1" pos="0.0 0.0 0.0" range="-30 30" type="hinge"/>
          <geom name="quadruped_back_left_leg" fromto="0.0 0.0 0.0 -0.2 -0.2 0.0" size="0.08" type="capsule"/>
          <body name="quadruped_back_left_knee" pos="-0.2 -0.2 0">
            <joint name="quadruped_back_left_ankle" axis="-1 1 0" pos="0.0 0.0 0.0" range="-70 -30" type="hinge"/>
            <geom name="quadruped_back_left_ankle" fromto="0.0 0.0 0.0 -0.4 -0.4 0.0" size="0.08" type="capsule"/>
            <geom name="quadruped_back_left_foot" pos="-0.4 -0.4 0" size="0.08" type="sphere" mass="0"/>
            <site name="quadruped_back_left_foot" pos="-0.435 -0.435 0" size="0.03" type="sphere"/>
          </body>
        </body>
      </body>

      <body name="quadruped_back_right_leg" pos="0 0 0">
        <geom name="quadruped_back_right_aux" fromto="0.0 0.0 0.0 0.2 -0.2 0.0" size="0.08" type="capsule"/>
        <body name="quadruped_back_right_aux" pos="0.2 -0.2 0">
          <joint name="quadruped_back_right_hip" axis="0 0 1" pos="0.0 0.0 0.0" range="-30 30" type="hinge"/>
          <geom name="quadruped_back_right_leg" fromto="0.0 0.0 0.0 0.2 -0.2 0.0" size="0.08" type="capsule"/>
          <body name="quadruped_back_right_knee" pos="0.2 -0.2 0">
            <joint name="quadruped_back_right_ankle" axis="1 1 0" pos="0.0 0.0 0.0" range="30 70" type="hinge"/>
            <geom name="quadruped_back_right_ankle" fromto="0.0 0.0 0.0 0.4 -0.4 0.0" size="0.08" type="capsule"/>
            <geom name="quadruped_back_right_foot" pos="0.4 -0.4 0" size="0.08" type="sphere" mass="0"/>
            <site name="quadruped_back_right_foot" pos="0.435 -0.435 0" size="0.03" type="sphere"/>
          </body>
        </body>
      </body>
    </body>
  </worldbody>

  <sensor>
    <gyro name="imu_ang_vel" site="imu" noise="0.01" />
    <accelerometer name="imu_lin_acc" site="imu" noise="0.01" />
    <velocimeter name="imu_lin_vel" site="imu" />
    <subtreeangmom name="root_angmom" body="quadruped"/>
  </sensor>

<asset>
    <material name="body" rgba=".7 .5 .3 1" specular="0.9" shininess="0.8"/>
  </asset>

  <keyframe>
    <key name="home" qpos="0 0.0 0.55 1.0 0.0 0.0 0.0 0.0 1.0 0.0 -1.0 0.0 -1.0 0.0 1.0"/>
  </keyframe>
</mujoco>
