<mujoco model="spot">
  <compiler angle="radian" meshdir="assets"/>

  <default>
    <default class="spot">
      <geom conaffinity="0" contype="0"/>
      <joint actuatorfrcrange="-1000 1000" damping="1" frictionloss="0.1"/>
      <position kp="500"/> 
      <default class="visual">
        <geom group="2" type="mesh" contype="0" conaffinity="0"/>
      </default>
      <default class="collision">
        <default class="foot_collision">
          <geom type="sphere" conaffinity="1" contype="1" size="0.036" pos="0 0 -0.3365" priority="1" condim="3" friction="0.8 0.6 0.6" group="3"/>
        </default>
      </default>
    </default>
  </default>

  <worldbody>
    <body name="body" childclass="spot" pos="0 0 .75">
      <freejoint name="freejoint"/>
      <inertial pos="0.0063944 -9.81216e-05 0.000911379" mass="32.86" diaginertia="0.13144 0.13144 0.13144"/>
      <site name="imu" size="0.01" pos="0 0 0" group="1"/>
      <geom mesh="body_0" material="BlackAbs" class="visual"/>
      <geom mesh="body_1" material="wrap" class="visual"/>
      <body name="fl_hip" pos="0.29785 0.055 0">
        <inertial pos="-0.00537435 0.0128418 9.87523e-05" quat="1 1 -1 1" mass="1.68"
          diaginertia="0.00226544 0.00211474 0.00181296"/>
        <joint name="fl_hx" axis="1 0 0" range="-0.785398 0.785398"/>
        <geom material="BlackAbs" mesh="front_left_hip" class="visual"/>
        <body name="fl_uleg" pos="0 0.1108 0">
          <inertial pos="0.00514237 -0.00243237 -0.121009" mass="2.34" diaginertia="0.0275596 0.0273549 0.00284815"/>
          <joint name="fl_hy" axis="0 1 0" range="-0.898845 2.29511"/>
          <geom mesh="front_left_upper_leg_0" material="wrap" class="visual"/>
          <geom mesh="front_left_upper_leg_1" material="BlackAbs" class="visual"/>
          <body name="fl_lleg" pos="0.025 0 -0.32">
            <inertial pos="0.00225794 4.6076e-05 -0.180082" quat="1 0 0 1" mass="0.35"
              diaginertia="0.00405032 0.00399902 0.00014934"/>
            <joint name="fl_kn" axis="0 1 0" range="-2.7929 -0.254402"/>
            <geom material="BlackAbs" mesh="front_left_lower_leg" class="visual"/>
            <geom name="FL" class="foot_collision"/>
            <site name="fl_foot" size="0.01" pos="0 0 -0.3365" group="1"/>
          </body>
        </body>
      </body>
      <body name="fr_hip" pos="0.29785 -0.055 0">
        <inertial pos="-0.00537435 -0.0128418 -9.87523e-05" quat="1 1 -1 1" mass="1.68"
          diaginertia="0.00226544 0.00211474 0.00181296"/>
        <joint name="fr_hx" axis="1 0 0" range="-0.785398 0.785398"/>
        <geom material="BlackAbs" mesh="front_right_hip" class="visual"/>
        <body name="fr_uleg" pos="0 -0.1108 0">
          <inertial pos="0.00514237 0.00243237 -0.121009" mass="2.34" diaginertia="0.0275596 0.0273549 0.00284815"/>
          <joint name="fr_hy" axis="0 1 0" range="-0.898845 2.24363"/>
          <geom mesh="front_right_upper_leg_0" material="wrap" class="visual"/>
          <geom mesh="front_right_upper_leg_1" material="BlackAbs" class="visual"/>
          <body name="fr_lleg" pos="0.025 0 -0.32">
            <inertial pos="0.00225794 4.6076e-05 -0.180082" quat="1 0 0 1" mass="0.35"
              diaginertia="0.00405032 0.00399902 0.00014934"/>
            <joint name="fr_kn" axis="0 1 0" range="-2.7929 -0.255648"/>
            <geom material="BlackAbs" mesh="front_right_lower_leg" class="visual"/>
            <geom name="FR" class="foot_collision"/>
            <site name="fr_foot" size="0.01" pos="0 0 -0.3365" group="1"/>
          </body>
        </body>
      </body>
      <body name="hl_hip" pos="-0.29785 0.055 0">
        <inertial pos="0.00537435 0.0128418 -9.87523e-05" quat="1 1 -1 1" mass="1.68"
          diaginertia="0.00226544 0.00211474 0.00181296"/>
        <joint name="hl_hx" axis="1 0 0" range="-0.785398 0.785398"/>
        <geom material="BlackAbs" mesh="rear_left_hip" class="visual"/>
        <body name="hl_uleg" pos="0 0.1108 0">
          <inertial pos="0.00514237 -0.00243237 -0.121009" mass="2.34" diaginertia="0.0275596 0.0273549 0.00284815"/>
          <joint name="hl_hy" axis="0 1 0" range="-0.898845 2.29511"/>
          <geom mesh="rear_left_upper_leg_0" material="wrap" class="visual"/>
          <geom mesh="rear_left_upper_leg_1" material="BlackAbs" class="visual"/>
          <body name="hl_lleg" pos="0.025 0 -0.32">
            <inertial pos="0.00225794 4.6076e-05 -0.180082" quat="1 0 0 1" mass="0.35"
              diaginertia="0.00405032 0.00399902 0.00014934"/>
            <joint name="hl_kn" axis="0 1 0" range="-2.7929 -0.247067"/>
            <geom material="BlackAbs" mesh="rear_left_lower_leg" class="visual"/>
            <geom name="HL" class="foot_collision"/>
            <site name="hl_foot" size="0.01" pos="0 0 -0.3365" group="1"/>
          </body>
        </body>
      </body>
      <body name="hr_hip" pos="-0.29785 -0.055 0">
        <inertial pos="0.00537435 -0.0128418 9.87523e-05" quat="1 1 -1 1" mass="1.68"
          diaginertia="0.00226544 0.00211474 0.00181296"/>
        <joint name="hr_hx" axis="1 0 0" range="-0.785398 0.785398"/>
        <geom material="BlackAbs" mesh="rear_right_hip" class="visual"/>
        <body name="hr_uleg" pos="0 -0.1108 0">
          <inertial pos="0.00514237 0.00243237 -0.121009" mass="2.34" diaginertia="0.0275596 0.0273549 0.00284815"/>
          <joint name="hr_hy" axis="0 1 0" range="-0.898845 2.29511"/>
          <geom mesh="rear_right_upper_leg_0" material="wrap" class="visual"/>
          <geom mesh="rear_right_upper_leg_1" material="BlackAbs" class="visual"/>
          <body name="hr_lleg" pos="0.025 0 -0.32">
            <inertial pos="0.00225794 4.6076e-05 -0.180082" quat="1 0 0 1" mass="0.35"
              diaginertia="0.00405032 0.00399902 0.00014934"/>
            <joint name="hr_kn" axis="0 1 0" range="-2.7929 -0.248282"/>
            <geom material="BlackAbs" mesh="rear_left_lower_leg" class="visual"/>
            <geom name="HR" class="foot_collision"/>
            <site name="hr_foot" size="0.01" pos="0 0 -0.3365" group="1"/>
          </body>
        </body>
      </body>
    </body>
  </worldbody>

  <contact>
    <exclude body1="body" body2="fl_uleg"/>
    <exclude body1="body" body2="fr_uleg"/>
    <exclude body1="body" body2="hl_uleg"/>
    <exclude body1="body" body2="hr_uleg"/>
  </contact>

  <sensor>
    <gyro name="imu_ang_vel" site="imu"/>
    <accelerometer name="imu_lin_acc" site="imu"/>
    <velocimeter name="imu_lin_vel" site="imu"/>
    <subtreeangmom name="root_angmom" body="body"/>
  </sensor>

  <asset>
    <material name="BlackAbs" rgba="0.1 0.1 0.1 1"/>
    <material name="wrap" rgba="0.878431 0.666666 0.227450 1"/>

    <mesh file="body_0.obj"/>
    <mesh file="body_1.obj"/>
    <mesh file="front_left_hip.obj"/>
    <mesh file="front_left_upper_leg_0.obj"/>
    <mesh file="front_left_upper_leg_1.obj"/>
    <mesh file="front_left_lower_leg.obj"/>
    <mesh file="front_right_hip.obj"/>
    <mesh file="front_right_upper_leg_0.obj"/>
    <mesh file="front_right_upper_leg_1.obj"/>
    <mesh file="front_right_lower_leg.obj"/>
    <mesh file="rear_left_hip.obj"/>
    <mesh file="rear_left_upper_leg_0.obj"/>
    <mesh file="rear_left_upper_leg_1.obj"/>
    <mesh file="rear_left_lower_leg.obj"/>
    <mesh file="rear_right_hip.obj"/>
    <mesh file="rear_right_upper_leg_0.obj"/>
    <mesh file="rear_right_upper_leg_1.obj"/>
    <mesh file="rear_right_lower_leg.obj"/>
    <mesh file="body_collision.obj"/>
    <mesh file="left_upper_leg_collision.obj"/>
    <mesh file="left_lower_leg_collision.obj"/>
    <mesh file="right_upper_leg_collision.obj"/>
    <mesh file="right_lower_leg_collision.obj"/>
  </asset>
</mujoco>
