<mujoco model="velocity_anymal_c">
  <option timestep="0.005" iterations="10" ls_iterations="20" solver="Newton" integrator="implicitfast"/>
  <compiler angle="radian" meshdir="assets" texturedir="assets" autolimits="true"/>

  <default>
    <material specular="0" shininess="0.25"/>
    <default class="anymal_c">
      <position kp="100" ctrlrange="-6.28 6.28" forcerange="-80 80"/>
      <joint damping="1" frictionloss="0.1"/>

      <default class="visual">
        <geom type="mesh" contype="0" conaffinity="0" group="2"/>
        <default class="visual_zflip">
          <geom quat="0 0 0 1"/>
        </default>
      </default>
      <default class="collision">
        <geom group="1" type="cylinder" contype="0" conaffinity="0"/>
        <default class="foot_collision">
          <geom type="sphere" size="0.03" pos="0 0 0.02325" priority="1" friction="0.6" conaffinity="1" contype="1"/>
        </default>
      </default>
    </default>

  </default>


  <worldbody>
    <geom name="floor" size="0 0 0.01" type="plane" material="groundplane" contype="1" conaffinity="1" priority="1" friction="0.6" condim="3"/>

    <body name="base" pos="0 0 0.62" quat="0 0 0 1" childclass="anymal_c">
      <freejoint name="root"/>
      <site name="imu" size="0.01" pos="0 0 0"/>
      <inertial mass="19.2035" pos="0.0025 0 0.0502071" quat="0.5 0.5 0.5 0.5" diaginertia="0.639559 0.624031 0.217374"/>
      <geom mesh="base_0" material="green" class="visual"/>
      <geom mesh="base_1" material="yellow" class="visual"/>
      <geom mesh="base_2" material="red" class="visual"/>
      <geom mesh="base_3" material="black_plastic" class="visual"/>
      <geom mesh="base_4" material="lwl" class="visual"/>
      <geom mesh="base_5" material="base" class="visual"/>
      <geom class="collision" size="0.29 0.07 0.09" type="box"/>
      <geom class="collision" size="0.09 0.0725" pos="0.2175 0.07 0" quat="1 0 1 0"/>
      <geom class="collision" size="0.09 0.0725" pos="-0.2175 0.07 0" quat="1 0 1 0"/>
      <geom class="collision" size="0.09 0.0725" pos="0.2175 -0.07 0" quat="1 0 1 0"/>
      <geom class="collision" size="0.09 0.0725" pos="-0.2175 -0.07 0" quat="1 0 1 0"/>
      <geom material="top_shell" mesh="top_shell" class="visual"/>
      <geom material="bottom_shell" mesh="bottom_shell" class="visual"/>
      <geom material="remote" mesh="remote" class="visual"/>
      <geom material="handle" mesh="handle" class="visual"/>
      <geom pos="0.4145 0 0" material="face" mesh="face" class="visual"/>
      <geom class="collision" size="0.055 0.07 0.09" pos="0.4695 0 0" type="box"/>
      <geom class="collision" size="0.09 0.055" pos="0.4695 0.07 0" quat="1 0 1 0"/>
      <geom class="collision" size="0.09 0.055" pos="0.4695 -0.07 0" quat="1 0 1 0"/>
      <geom pos="0.46165 0 -0.0292" quat="0.965926 0 0.258819 0" material="depth_camera" mesh="depth_camera"
        class="visual"/>
      <geom pos="0.513 0 0.01497" material="wide_angle_camera" mesh="wide_angle_camera" class="visual"/>
      <geom pos="-0.4145 0 0" material="face" mesh="face" class="visual_zflip"/>
      <geom class="collision" size="0.055 0.07 0.09" pos="-0.4695 0 0" quat="0 0 0 1" type="box"/>
      <geom class="collision" size="0.09 0.055" pos="-0.4695 -0.07 0" quat="0 -1 0 1"/>
      <geom class="collision" size="0.09 0.055" pos="-0.4695 0.07 0" quat="0 -1 0 1"/>
      <geom pos="-0.46165 0 -0.0292" quat="0 -0.258819 0 0.965926" material="depth_camera" mesh="depth_camera"
        class="visual"/>
      <geom pos="-0.513 0 0.01497" material="wide_angle_camera" mesh="wide_angle_camera" class="visual_zflip"/>
      <geom material="battery" mesh="battery" class="visual"/>
      <geom pos="0 0.07646 0.02905" quat="0.683013 -0.183013 0.183013 0.683013" material="depth_camera"
        mesh="depth_camera" class="visual"/>
      <geom pos="0 -0.07646 0.02905" quat="0.683013 0.183013 0.183013 -0.683013" material="depth_camera"
        mesh="depth_camera" class="visual"/>
      <geom pos="-0.364 0 0.0735" material="lidar_cage" mesh="lidar_cage" class="visual"/>
      <geom class="collision" size="0.07 0.06" pos="-0.364 0 0.1335"/>
      <geom pos="-0.364 0 0.1422" quat="1 0 0 -1" material="lidar" mesh="lidar" class="visual"/>
      <geom pos="0.2999 0.104 0" quat="0.258819 0.965926 0 0" material="drive" mesh="drive" class="visual"/>
      <geom pos="0.2999 -0.104 0" quat="0.258819 -0.965926 0 0" material="drive" mesh="drive" class="visual"/>
      <geom pos="-0.2999 0.104 0" quat="0 0 0.965926 -0.258819" material="drive" mesh="drive" class="visual"/>
      <geom pos="-0.2999 -0.104 0" quat="0 0 -0.965926 -0.258819" material="drive" mesh="drive" class="visual"/>
      <geom pos="0.116 0 0.073" material="hatch" mesh="hatch" class="visual"/>
      <body name="LF_HIP" pos="0.2999 0.104 0" quat="0.258819 0.965926 0 0">
        <inertial mass="2.781" pos="0.0566606 -0.015294 -0.00829784" quat="-0.127978 0.709783 -0.135278 0.679359"
          diaginertia="0.00585729 0.00491868 0.00329081"/>
        <joint name="LF_HAA" axis="1 0 0" range="-0.72 0.49"/>
        <geom quat="0.258819 -0.965926 0 0" material="hip_l" mesh="hip_l" class="visual"/>
        <geom pos="0.0599 -0.0725816 -0.041905" quat="0.183013 -0.683013 0.683013 0.183013" material="drive"
          mesh="drive" class="visual"/>
        <geom class="collision" size="0.05 0.07" pos="0.0599 -0.0119598 -0.006905"
          quat="-0.353553 -0.612372 0.612372 -0.353553"/>
        <body name="LF_THIGH" pos="0.0599 -0.0725816 -0.041905" quat="0.183013 -0.683013 0.683013 0.183013">
          <inertial mass="3.071" pos="0.0308147 4.64995e-05 -0.245696" quat="0.993166 -0.00515309 -0.0806592 0.0841972"
            diaginertia="0.03025 0.0298943 0.00418465"/>
          <joint name="LF_HFE" axis="1 0 0" range="-9.42478 9.42478"/>
          <geom quat="1 0 0 -1" material="thigh" mesh="thigh" class="visual"/>
          <geom class="collision" size="0.065 0.04" pos="0.04 0 0" quat="0.5 0.5 -0.5 -0.5"/>
          <geom class="collision" size="0.0375 0.03 0.141314" pos="0.03 0 -0.141314" quat="1 0 0 -1" type="box"/>
          <geom pos="0.1003 0 -0.285" material="drive" mesh="drive" class="visual"/>
          <geom class="collision" size="0.05 0.07" pos="0.0303 0 -0.285" quat="1 0 1 0"/>
          <body name="LF_SHANK" pos="0.1003 0 -0.285">
            <inertial mass="0.58842" pos="0.005462 -0.0612528 -0.0806598"
              quat="0.992934 -0.115904 -0.00105487 -0.0254421" diaginertia="0.0101637 0.00923838 0.00111927"/>
            <joint name="LF_KFE" axis="1 0 0" range="-9.42478 9.42478"/>
            <geom quat="1 0 0 -1" material="shank_l" mesh="shank_l" class="visual"/>
            <geom class="collision" size="0.06 0.02" pos="0.02 0 0" quat="0.5 0.5 -0.5 -0.5"/>
            <geom class="collision" size="0.057499 0.03375 0.019" pos="0.02 -0.057499 0" quat="0.5 0.5 -0.5 -0.5"
              type="box"/>
            <geom pos="0.01305 -0.08795 -0.33797" quat="0.382683 0 0 -0.92388" material="foot" mesh="foot"
              class="visual"/>
            <geom class="collision" size="0.0175 0.141252" pos="0.01305 -0.08795 -0.168985" quat="1 0 0 -1"/>
            <geom name="LF_FOOT" class="foot_collision" pos="0.01305 -0.08795 -0.31547" quat="1 0 0 -1"/>
            <site name="LF_foot" pos="0.01305 -0.08795 -0.31547" size="0.01"/>
          </body>
        </body>
      </body>
      <body name="RF_HIP" pos="0.2999 -0.104 0" quat="0.258819 -0.965926 0 0">
        <inertial mass="2.781" pos="0.0567633 0.015294 -0.00829784" quat="0.13524 0.679072 0.127985 0.710065"
          diaginertia="0.00585928 0.0049205 0.00329064"/>
        <joint name="RF_HAA" axis="1 0 0" range="-0.49 0.72"/>
        <geom quat="0.258819 0.965926 0 0" material="hip_r" mesh="hip_r" class="visual"/>
        <geom pos="0.0599 0.0725816 -0.041905" quat="0.183013 0.683013 0.683013 -0.183013" material="drive" mesh="drive"
          class="visual"/>
        <geom class="collision" size="0.05 0.07" pos="0.0599 0.0119598 -0.006905"
          quat="-0.353553 0.612372 0.612372 0.353553"/>
        <body name="RF_THIGH" pos="0.0599 0.0725816 -0.041905" quat="0.183013 0.683013 0.683013 -0.183013">
          <inertial mass="3.071" pos="0.0308147 4.64995e-05 -0.245696" quat="0.992775 -0.00512735 -0.0806685 0.0886811"
            diaginertia="0.0302511 0.0298933 0.0041845"/>
          <joint name="RF_HFE" axis="-1 0 0" range="-9.42478 9.42478"/>
          <geom quat="1 0 0 -1" material="thigh" mesh="thigh" class="visual"/>
          <geom class="collision" size="0.065 0.04" pos="0.04 0 0" quat="0.5 0.5 0.5 0.5"/>
          <geom class="collision" size="0.0375 0.03 0.141314" pos="0.03 0 -0.141314" quat="1 0 0 1" type="box"/>
          <geom pos="0.1003 0 -0.285" material="drive" mesh="drive" class="visual"/>
          <geom class="collision" size="0.05 0.07" pos="0.0303 0 -0.285" quat="1 0 1 0"/>
          <body name="RF_SHANK" pos="0.1003 0 -0.285">
            <inertial mass="0.58842" pos="0.005462 0.0612528 -0.0806598" quat="0.992934 0.115904 -0.00105487 0.0254421"
              diaginertia="0.0101637 0.00923838 0.00111927"/>
            <joint name="RF_KFE" axis="-1 0 0" range="-9.42478 9.42478"/>
            <geom quat="1 0 0 1" material="shank" mesh="shank_r" class="visual"/>
            <geom class="collision" size="0.06 0.02" pos="0.02 0 0" quat="0.5 0.5 0.5 0.5"/>
            <geom class="collision" size="0.057499 0.03375 0.019" pos="0.02 0.057499 0" quat="0.5 0.5 0.5 0.5"
              type="box"/>
            <geom pos="0.01305 0.08795 -0.33797" quat="0.382683 0 0 0.92388" material="foot" mesh="foot" class="visual"/>
            <geom class="collision" size="0.0175 0.141252" pos="0.01305 0.08795 -0.168985" quat="1 0 0 1"/>
            <geom name="RF_FOOT" class="foot_collision" pos="0.01305 0.08795 -0.31547" quat="1 0 0 1"/>
            <site name="RF_foot" pos="0.01305 0.08795 -0.31547" size="0.01"/>
          </body>
        </body>
      </body>
      <body name="LH_HIP" pos="-0.2999 0.104 0" quat="0 0 0.965926 -0.258819">
        <inertial mass="2.781" pos="0.0567633 0.015294 -0.00829784" quat="0.13524 0.679072 0.127985 0.710065"
          diaginertia="0.00585928 0.0049205 0.00329064"/>
        <joint name="LH_HAA" axis="-1 0 0" range="-0.72 0.49"/>
        <geom quat="-0.258819 -0.965926 0 0" material="hip_r" mesh="hip_r" class="visual"/>
        <geom pos="0.0599 0.0725816 -0.041905" quat="0.183013 0.683013 0.683013 -0.183013" material="drive" mesh="drive"
          class="visual"/>
        <geom class="collision" size="0.05 0.07" pos="0.0599 0.0119598 -0.006905"
          quat="-0.353553 0.612372 0.612372 0.353553"/>
        <body name="LH_THIGH" pos="0.0599 0.0725816 -0.041905" quat="0.183013 0.683013 0.683013 -0.183013">
          <inertial mass="3.071" pos="0.0308147 4.64995e-05 -0.245696" quat="0.992775 -0.00512735 -0.0806685 0.0886811"
            diaginertia="0.0302511 0.0298933 0.0041845"/>
          <joint name="LH_HFE" axis="1 0 0" range="-9.42478 9.42478"/>
          <geom quat="1 0 0 -1" material="thigh" mesh="thigh" class="visual"/>
          <geom class="collision" size="0.065 0.04" pos="0.04 0 0" quat="0.5 0.5 -0.5 -0.5"/>
          <geom class="collision" size="0.0375 0.03 0.141314" pos="0.03 0 -0.141314" quat="1 0 0 -1" type="box"/>
          <geom pos="0.1003 0 -0.285" material="drive" mesh="drive" class="visual"/>
          <geom class="collision" size="0.05 0.07" pos="0.0303 0 -0.285" quat="1 0 1 0"/>
          <body name="LH_SHANK" pos="0.1003 0 -0.285">
            <inertial mass="0.58842" pos="0.005462 0.0612528 -0.0806598" quat="0.992934 0.115904 -0.00105487 0.0254421"
              diaginertia="0.0101637 0.00923838 0.00111927"/>
            <joint name="LH_KFE" axis="1 0 0" range="-9.42478 9.42478"/>
            <geom quat="-1 0 0 -1" material="shank" mesh="shank_r" class="visual"/>
            <geom class="collision" size="0.06 0.02" pos="0.02 0 0" quat="0.5 0.5 -0.5 -0.5"/>
            <geom class="collision" size="0.057499 0.03375 0.019" pos="0.02 0.057499 0" quat="0.5 0.5 -0.5 -0.5"
              type="box"/>
            <geom pos="0.01305 0.08795 -0.33797" quat="-0.382683 0 0 -0.92388" material="foot" mesh="foot"
              class="visual"/>
            <geom class="collision" size="0.0175 0.141252" pos="0.01305 0.08795 -0.168985" quat="1 0 0 -1"/>
            <geom name="LH_FOOT" class="foot_collision" pos="0.01305 0.08795 -0.31547" quat="1 0 0 -1"/>
            <site name="LH_foot" pos="0.01305 0.08795 -0.31547" size="0.01"/>
          </body>
        </body>
      </body>
      <body name="RH_HIP" pos="-0.2999 -0.104 0" quat="0 0 -0.965926 -0.258819">
        <inertial mass="2.781" pos="0.0566606 -0.015294 -0.00829784" quat="-0.127978 0.709783 -0.135278 0.679359"
          diaginertia="0.00585729 0.00491868 0.00329081"/>
        <joint name="RH_HAA" axis="-1 0 0" range="-0.49 0.72"/>
        <geom quat="-0.258819 0.965926 0 0" material="hip_l" mesh="hip_l" class="visual"/>
        <geom pos="0.0599 -0.0725816 -0.041905" quat="-0.183013 0.683013 -0.683013 -0.183013" material="drive"
          mesh="drive" class="visual"/>
        <geom class="collision" size="0.05 0.07" pos="0.0599 -0.0119598 -0.006905"
          quat="0.353553 0.612372 -0.612372 0.353553"/>
        <body name="RH_THIGH" pos="0.0599 -0.0725816 -0.041905" quat="-0.183013 0.683013 -0.683013 -0.183013">
          <inertial mass="3.071" pos="0.0308147 4.64995e-05 -0.245696" quat="0.993166 -0.00515309 -0.0806592 0.0841972"
            diaginertia="0.03025 0.0298943 0.00418465"/>
          <joint name="RH_HFE" axis="-1 0 0" range="-9.42478 9.42478"/>
          <geom quat="1 0 0 -1" material="thigh" mesh="thigh" class="visual"/>
          <geom class="collision" size="0.065 0.04" pos="0.04 0 0" quat="0.5 0.5 0.5 0.5"/>
          <geom class="collision" size="0.0375 0.03 0.141314" pos="0.03 0 -0.141314" quat="1 0 0 1" type="box"/>
          <geom pos="0.1003 0 -0.285" material="drive" mesh="drive" class="visual"/>
          <geom class="collision" size="0.05 0.07" pos="0.0303 0 -0.285" quat="1 0 1 0"/>
          <body name="RH_SHANK" pos="0.1003 0 -0.285">
            <inertial mass="0.58842" pos="0.005462 -0.0612528 -0.0806598"
              quat="0.992934 -0.115904 -0.00105487 -0.0254421" diaginertia="0.0101637 0.00923838 0.00111927"/>
            <joint name="RH_KFE" axis="-1 0 0" range="-9.42478 9.42478"/>
            <geom quat="1 0 0 -1" material="shank_l" mesh="shank_l" class="visual"/>
            <geom class="collision" size="0.06 0.02" pos="0.02 0 0" quat="0.5 0.5 0.5 0.5"/>
            <geom class="collision" size="0.057499 0.03375 0.019" pos="0.02 -0.057499 0" quat="0.5 0.5 0.5 0.5" type="box"/>
            <geom pos="0.01305 -0.08795 -0.33797" quat="0.382683 0 0 -0.92388" material="foot" mesh="foot"
              class="visual"/>
            <geom class="collision" size="0.0175 0.141252" pos="0.01305 -0.08795 -0.168985" quat="1 0 0 1"/>
            <geom name="RH_FOOT" class="foot_collision" pos="0.01305 -0.08795 -0.31547" quat="1 0 0 1"/>
            <site name="RH_foot" pos="0.01305 -0.08795 -0.31547" size="0.01"/>
          </body>
        </body>
      </body>
    </body>
  </worldbody>

  <contact>
    <exclude body1="base" body2="LF_THIGH"/>
    <exclude body1="base" body2="RF_THIGH"/>
    <exclude body1="base" body2="LH_THIGH"/>
    <exclude body1="base" body2="RH_THIGH"/>
  </contact>

  <actuator>
    <position class="anymal_c" joint="LF_HAA" name="LF_HAA"/>
    <position class="anymal_c" joint="LF_HFE" name="LF_HFE"/>
    <position class="anymal_c" joint="LF_KFE" name="LF_KFE"/>
    <position class="anymal_c" joint="RF_HAA" name="RF_HAA"/>
    <position class="anymal_c" joint="RF_HFE" name="RF_HFE"/>
    <position class="anymal_c" joint="RF_KFE" name="RF_KFE"/>
    <position class="anymal_c" joint="LH_HAA" name="LH_HAA"/>
    <position class="anymal_c" joint="LH_HFE" name="LH_HFE"/>
    <position class="anymal_c" joint="LH_KFE" name="LH_KFE"/>
    <position class="anymal_c" joint="RH_HAA" name="RH_HAA"/>
    <position class="anymal_c" joint="RH_HFE" name="RH_HFE"/>
    <position class="anymal_c" joint="RH_KFE" name="RH_KFE"/>
  </actuator>

  <sensor>
    <gyro name="gyro" site="imu" noise="0.01"/>
    <accelerometer name="accelerometer" site="imu" noise="0.01"/>
    <velocimeter name="local_linvel" site="imu"/>
    <framezaxis name="gravity" objtype="site" objname="imu"/>
    <framelinvel name="global_linvel" objtype="site" objname="imu"/>
    <frameangvel name="global_angvel" objtype="site" objname="imu"/>

    <contact name="LF_foot_floor_contact" geom1="LF_FOOT" geom2="floor" reduce="mindist" num="1" data="found"/>
    <contact name="RF_foot_floor_contact" geom1="RF_FOOT" geom2="floor" reduce="mindist" num="1" data="found"/>
    <contact name="LH_foot_floor_contact" geom1="LH_FOOT" geom2="floor" reduce="mindist" num="1" data="found"/>
    <contact name="RH_foot_floor_contact" geom1="RH_FOOT" geom2="floor" reduce="mindist" num="1" data="found"/>

    <framelinvel name="LF_foot_global_linvel" objtype="site" objname="LF_foot"/>
    <framelinvel name="RF_foot_global_linvel" objtype="site" objname="RF_foot"/>
    <framelinvel name="LH_foot_global_linvel" objtype="site" objname="LH_foot"/>
    <framelinvel name="RH_foot_global_linvel" objtype="site" objname="RH_foot"/>
    <subtreeangmom name="root_angmom" body="base"/>
  </sensor>

  <keyframe>
    <key name="home"
      qpos="
       0.0 0.0 0.56 1.0 0.0 0.0 0.0
       0.0 0.5235987755982988 -0.7853981 0.0 0.5235987755982988 -0.7853981 0.0 -0.5235987755982988 0.7853981 0.0 -0.5235987755982988 0.7853981"/>
  </keyframe>

  <asset>
    <material name="black_plastic" rgba="0.007 0.007 0.007 1"/>
    <material name="green" rgba="0.052 0.178 0.033 1"/>
    <material name="red" rgba="0.178 0.006 0.005 1"/>
    <material name="yellow" rgba="0.178 0.119 0.006 1"/>
    <material name="lwl" rgba="0.8 0.8 0.8 1"/>
    <material name="base" texture="base"/>
    <material name="top_shell" texture="top_shell"/>
    <material name="bottom_shell" texture="bottom_shell"/>
    <material name="hip_l" texture="hip_l"/>
    <material name="thigh" texture="thigh"/>
    <material name="shank_l" texture="shank_l"/>
    <material name="foot" texture="foot"/>
    <material name="hip_r" texture="hip_r"/>
    <material name="shank" texture="shank_r"/>
    <material name="hatch" texture="hatch"/>
    <material name="remote" texture="remote"/>
    <material name="handle" texture="handle"/>
    <material name="face" texture="face"/>
    <material name="depth_camera" texture="depth_camera"/>
    <material name="wide_angle_camera" texture="wide_angle_camera"/>
    <material name="battery" texture="battery"/>
    <material name="lidar_cage" texture="lidar_cage"/>
    <material name="lidar" texture="lidar"/>
    <material name="drive" texture="drive"/>

    <texture type="2d" name="base" file="base.png"/>
    <texture type="2d" name="top_shell" file="top_shell.png"/>
    <texture type="2d" name="bottom_shell" file="bottom_shell.png"/>
    <texture type="2d" name="remote" file="remote.png"/>
    <texture type="2d" name="hatch" file="hatch.png"/>
    <texture type="2d" name="handle" file="handle.png"/>
    <texture type="2d" name="face" file="face.png"/>
    <texture type="2d" name="battery" file="battery.png"/>
    <texture type="2d" name="lidar_cage" file="lidar_cage.png"/>
    <texture type="2d" name="depth_camera" file="depth_camera.png"/>
    <texture type="2d" name="wide_angle_camera" file="wide_angle_camera.png"/>
    <texture type="2d" name="lidar" file="lidar.png"/>
    <texture type="2d" name="drive" file="drive.png"/>
    <texture type="2d" name="hip_l" file="hip_l.png"/>
    <texture type="2d" name="shank_l" file="shank_l.png"/>
    <texture type="2d" name="foot" file="foot.png"/>
    <texture type="2d" name="thigh" file="thigh.png"/>
    <texture type="2d" name="shank_r" file="shank_r.png"/>
    <texture type="2d" name="hip_r" file="hip_r.png"/>

    <mesh file="base_0.obj"/>
    <mesh file="base_1.obj"/>
    <mesh file="base_2.obj"/>
    <mesh file="base_3.obj"/>
    <mesh file="base_4.obj"/>
    <mesh file="base_5.obj"/>
    <mesh file="top_shell.obj"/>
    <mesh file="bottom_shell.obj"/>
    <mesh file="remote.obj"/>
    <mesh file="handle.obj"/>
    <mesh file="face.obj"/>
    <mesh file="wide_angle_camera.obj"/>
    <mesh file="depth_camera.obj"/>
    <mesh file="battery.obj"/>
    <mesh file="lidar_cage.obj"/>
    <mesh file="lidar.obj"/>
    <mesh file="drive.obj"/>
    <mesh file="hip_l.obj"/>
    <mesh file="thigh.obj"/>
    <mesh file="shank_l.obj"/>
    <mesh file="foot.obj"/>
    <mesh file="hip_r.obj"/>
    <mesh file="hatch.obj"/>
    <mesh file="shank_r.obj"/>

    <texture type="skybox" builtin="gradient" rgb1="1 1 1" rgb2="1 1 1" width="800" height="800"/>
    <texture type="2d" name="groundplane" builtin="checker" mark="edge" rgb1="1 1 1" rgb2="1 1 1" markrgb="0 0 0" width="300" height="300"/>
    <material name="groundplane" texture="groundplane" texuniform="true" texrepeat="5 5" reflectance="0"/>
  </asset>
</mujoco>
